<?xml version="1.0"?>

<robot xmlns:xacro="http://ros.org/wiki/xacro" name="jackal_wheel">

  <xacro:property name="wheel_mass" value="0.477" />
  <xacro:macro name="wheel" params="prefix ns *joint_pose">
    <link name="${prefix}_wheel_link">
      <visual>
        <origin xyz="0 0 0" rpy="${PI/2} 0 0" />
        <geometry>
          <mesh filename="package://ipb_ros2_sim/description/jackal/meshes/jackal-wheel.stl" />
        </geometry>
        <material name="black" />
      </visual>
      <collision>
        <origin xyz="0 0 0" rpy="${PI/2} 0 0" />
        <geometry>
          <cylinder radius="${wheel_radius}" length="${wheel_width}" />
        </geometry>
      </collision>
      <inertial>
        <origin xyz="0 0 0" rpy="0 0 0" />
        <mass value="${wheel_mass}" />
        <inertia
          ixx="0.0013" ixy="0" ixz="0"
          iyy="0.0024" iyz="0"
          izz="0.0013" />
      </inertial>
    </link>


    <joint name="${prefix}_wheel" type="continuous">
      <parent link="${ns}chassis_link" />
      <child link="${prefix}_wheel_link" />
      <xacro:insert_block name="joint_pose" />
      <axis xyz="0 1 0" />
    </joint>
  </xacro:macro>
</robot>